Workbook

Sheet Sheet1
B2: 배수유역
B3: 구 분 | C3: 면 적 | E3: 비 고 | M3: 구 분 | N3: 강우강도식
C4: ㎡ | D4: ha | I4: 입력 | M4: 6차 다항식
B5: 배수유역① | C5: 16576 | D5: =SUM(C5/10000) -> 1.6576 | I5: 지역별입력 | N5: 여기서, | O5: I | P5: : | Q5: 강우강도(mm/hr) | R5: t | S5: : | T5: 유입시간(hr)
B6: 배수유역② | C6: 0 | D6: 0 | I6: 출력 | O6: ln | P6: : | Q6: 자연대수 | R6: a,b,c,d,e,f,g | S6: : | T6: 6차다항식의 계수값
B7: 배수유역3 | C7: 0
C8: 0
M9: 재현기간 | N9: Parameter
B10: 우수유출량 | M10: (년) | N10: a | O10: b | P10: c | Q10: d | R10: e | S10: f | T10: g | U10: t | V10: 10min | W10: =10/60 -> 0.16666667
B11: 구 분 | C11: 배수면적 | D11: 유출계수 | E11: 강우강도 | F11: 우수유출량 | H11: 비 고 | M11: 50 | N11: 4.39 | O11: -0.48 | P11: 0.04724 | Q11: -0.03226 | R11: 0.00138 | S11: 0.00164 | T11: -0.0026
C12: (ha) | E12: (mm/hr) | F12: (㎥/sec) | G12: (㎥/일)
B13: 배수유역① | C13: =D5 -> 1.6576 | D13: 0.63 | E13: 174.2 | F13: =ROUND(C13*D13*E13/360,4) -> 0.5053 | G13: =ROUND(F13*24*60*60,2) -> 43657.92
B14: 배수유역② | C14: =D6 -> 0 | D14: =D13 -> 0.63 | E14: =E13 -> 174.2 | F14: =C14*D14*E14/360 -> 0 | G14: =F14*24*60*60 -> 0 | M14: ln(I) | N14: =N11+O11*N15+P11*N15^2+Q11*N15^3+R11*N15^4+S11*N15^5+T11*N15^6 -> 5.485179
B15: 배수유역3 | C15: =D7 -> 0 | D15: =D13 -> 0.63 | E15: =E13 -> 174.2 | F15: =C15*D15*E15/360 -> 0 | G15: =F15*24*60*60 -> 0 | M15: ln(t) | N15: =LN(W10) -> -1.7917595
B16: 합 계 | C16: =SUM(C13:C14) -> 1.6576 | D16: - | E16: - | F16: =SUM(F13:F15) -> 0.5053 | G16: =SUM(G13:G15) -> 43657.92
M17: l | N17: =EXP(N14) -> 241.09209
B18: 토사유출량 | N18: 241.1
B19: 구 분 | C19: 배수면적 | D19: 토사유출량원단위 | E19: 토사비중 | F19: 강우일수 | G19: 토사유출량
C20: (ha) | D20: (㎥/ha․년) | E20: (ton/㎥) | F20: (일/10년) | G20: (ton/일)
B21: 배수유역① | C21: =D5 -> 1.6576 | D21: 300 | E21: 2.65 | F21: 105 | G21: =ROUND((C21*D21*E21)/F21,4) -> 12.5504
B22: 배수유역② | C22: =D6 -> 0 | D22: =D21 -> 300 | E22: =E21 -> 2.65 | F22: =F21 -> 105 | G22: =(C22*D22*E22)/F22 -> 0
B23: 배수유역3 | C23: =C15 -> 0 | D23: =D21 -> 300 | E23: =E21 -> 2.65 | F23: =F21 -> 105 | G23: =(C23*D23*E23)/F23 -> 0
B24: 합 계 | C24: =C16 -> 1.6576 | D24: - | E24: - | F24: - | G24: =SUM(G21:G23) -> 12.5504
B26: 무처리방류시 부유물질 산정
B27: 구 분 | C27: 우수유출량 | D27: 토사유출량 | E27: 부유물질농도 | F27: 비 고
C28: (㎥/일) | D28: (ton/일) | E28: (mg/ℓ)
B29: 배수유역① | C29: =G13 -> 43657.92 | D29: =G21 -> 12.5504 | E29: =ROUND(D29/C29*1000000,2) -> 287.47 | N29: 54.846
B30: 배수유역② | C30: =G14 -> 0 | D30: =G22 -> 0 | E30: =D30/C30*1000000 -> #DIV/0! | N30: =N29/(0.006+(1-0.006)*0.88) -> 62.274049 | O30: 62.27
B31: 배수유역3 | C31: =G15 -> 0 | D31: =G23 -> 0 | E31: =D31/C31*1000000 -> #DIV/0! | O31: =O30*0.006+(O30-O30*0.006)*0.88 -> 54.842434
B32: 합계(평균) | C32: =SUM(C29:C31) -> 43657.92 | D32: =SUM(D29:D31) -> 12.5504 | E32: =AVERAGE(E29:E31) -> #DIV/0!
B34: 합류점에서 혼합농도
B35: 구 분 | C35: 현 황 치 | E35: 가 중 치 | G35: 순간 혼합농도(단순혼합)
C36: 유량(㎥/sec) | D36: 농도(mg/ℓ) | E36: 유량(㎥/sec) | F36: 농도(mg/ℓ) | G36: 유량(㎥/sec) | H36: 농도(mg/ℓ)
C37: Q1 | D37: C1 | E37: Q2 | F37: C2 | G37: Q1+Q2 | H37: C
B38: W-2 | C38: 1.2 | D38: 7.4 | E38: =F16 -> 0.5053 | F38: =E29 -> 287.47 | G38: =ROUND(C38+E38,4) -> 1.7053 | H38: =ROUND(((C38*D38)+(E38*F38))/G38,2) -> 90.39
B40: 침사지 규모산정
B41: 구분 | C41: 우수유출량 | D41: 표면부하율 | E41: 침사지 | F41: 여유율 | G41: 침사지 | H41: 깊이 | I41: 침사지 | J41: 비고
C42: (㎥/일) | D42: (㎥/㎡․일) | E42: 소요면적(㎡) | F42: (%) | G42: 설치면적(㎡) | H42: (m) | I42: 용량(㎥)
B43: 배수유역① | C43: =G13 -> 43657.92 | D43: 639.36 | E43: =ROUND(C43/D43,0) -> 68 | F43: 15 | G43: =ROUND(E43*(F43/100)+E43,1) -> 78.2 | H43: 2 | I43: =G43*H43 -> 156.4
B44: 배수유역② | C44: =G14 -> 0 | D44: 639.36 | E44: =C44/D44 -> 0 | F44: 20 | G44: =E44*(F44/100)+E44 -> 0 | H44: 2 | I44: =G44*H44 -> 0
...

Sheet 침사지
A1: ◆ 임시침사지 설계
A2: 1) 침사지 설계 입력자료
A3: 유역명 | B3: 사업단계 | C3: 유역면적 (ha) | D3: 침사지 설계유량 (m3/s) | E3: 개발중 토사유출량
A4: 배수구역1 | B4: 공사시 | C4: 6.4388 | D4: =Sheet1!F13 -> 0.5053 | E4: 0
A5: 배수구역2 | B5: 공사시 | C5: 0 | D5: =Sheet1!F14 -> 0 | E5: 0
A8: 2) 소요수면적 및 포착효율 산정
A9: ▷ 지점명 : | B9: =A4 -> 배수구역1 | C9: ▷ 공정 : | D9: 공사시 | E9: ▷ 배수구역면적 : | F9: =Sheet1!D5 -> 1.6576 | G9: ha
A10: ▷ 설계유량 : | B10: =Sheet1!F13 -> 0.5053 | C10: m3/s | E10: ▷ 침사지면적 : | F10: 462.52 | G10: m2
A11: 입 경 (mm) | C11: 입경별 구성비 (%) | D11: 침강속도 (cm/s) | E11: 소요수면적 (m2) | F11: 포착율 (%) | G11: 입경별 포착율 (%)
A12: 2 | C12: 11.4 | D12: 10 | E12: =ROUND(1.2*$B$10/D12*100,0) -> 6 | F12: =ROUND(IF(100*$F$10/E12>=100,100,100*$F$10/E12),1) -> 100 | G12: =ROUND(C12*F12/100,1) -> 11.4
A13: 0.1 | C13: 56.3 | D13: 0.74 | E13: =ROUND(1.2*$B$10/D13*100,0) -> 82 | F13: =ROUND(IF(100*$F$10/E13>=100,100,100*$F$10/E13),1) -> 100 | G13: =ROUND(C13*F13/100,1) -> 56.3
A14: 0.05 | C14: 3.5 | D14: 0.17 | E14: =ROUND(1.2*$B$10/D14*100,0) -> 357 | F14: =ROUND(IF(100*$F$10/E14>=100,100,100*$F$10/E14),1) -> 100 | G14: =ROUND(C14*F14/100,1) -> 3.5
A15: 0.002 | C15: 30 | D15: 0.00028 | E15: =ROUND(1.2*$B$10/D15*100,0) -> 216557 | F15: =ROUND(IF(100*$F$10/E15>=100,100,100*$F$10/E15),1) -> 0.2 | G15: =ROUND(C15*F15/100,1) -> 0.1
A16: 0.001 | C16: 10.2 | D16: 6.9e-05 | E16: =ROUND(1.2*$B$10/D16*100,0) -> 878783 | F16: =ROUND(IF(100*$F$10/E16>=100,100,100*$F$10/E16),1) -> 0.1 | G16: =ROUND(C16*F16/100,1) -> 0
G17: =SUM(G12:G16) -> 71.3
A20: ▷ 지점명 : | B20: =A5 -> 배수구역2 | C20: ▷ 공정 : | D20: 공사시 | E20: ▷ 배수구역면적 : | F20: =Sheet1!D6 -> 0 | G20: ha
A21: ▷ 설계유량 : | B21: =Sheet1!F14 -> 0 | C21: m3/s | E21: ▷ 침사지면적 : | F21: =Sheet1!G44 -> 0 | G21: m2
A22: 입 경 (mm) | C22: 입경별 구성비 (%) | D22: 침강속도 (cm/s) | E22: 소요수면적 (m2) | F22: 포착율 (%) | G22: 입경별 포착율 (%)
A23: 2 | C23: 27.2 | D23: 10 | E23: =ROUND(1.2*$B$21/D23*100,0) -> 0 | F23: =ROUND(IF(100*$F$21/E23>=100,100,100*$F$21/E23),1) -> #DIV/0! | G23: =ROUND(C23*F23/100,1) -> #DIV/0!
A24: 0.1 | C24: 41.1 | D24: 0.74 | E24: =ROUND(1.2*$B$21/D24*100,0) -> 0 | F24: =ROUND(IF(100*$F$21/E24>=100,100,100*$F$21/E24),1) -> #DIV/0! | G24: =ROUND(C24*F24/100,1) -> #DIV/0!
A25: 0.05 | C25: 14.7 | D25: 0.17 | E25: =ROUND(1.2*$B$21/D25*100,0) -> 0 | F25: =ROUND(IF(100*$F$21/E25>=100,100,100*$F$21/E25),1) -> #DIV/0! | G25: =ROUND(C25*F25/100,1) -> #DIV/0!
A26: 0.002 | C26: 24.7 | D26: 0.00028 | E26: =ROUND(1.2*$B$21/D26*100,0) -> 0 | F26: =ROUND(IF(100*$F$21/E26>=100,100,100*$F$21/E26),1) -> #DIV/0! | G26: =ROUND(C26*F26/100,1) -> #DIV/0!
A27: 0.001 | C27: 19.5 | D27: 6.9e-05 | E27: =ROUND(1.2*$B$21/D27*100,0) -> 0 | F27: =ROUND(IF(100*$F$21/E27>=100,100,100*$F$21/E27),1) -> #DIV/0! | G27: =ROUND(C27*F27/100,1) -> #DIV/0!
G28: =SUM(G23:G27) -> #DIV/0!
A31: ▷ 지점명 : | B31: =#REF! -> #REF! | C31: ▷ 공정 : | D31: 공사시 | E31: ▷ 배수구역면적 : | F31: 4181 | G31: ha
A32: ▷ 설계유량 : | B32: =#REF! -> #REF! | C32: m3/s | E32: ▷ 침사지면적 : | F32: =Sheet1!#REF! -> #REF! | G32: m2
A33: 입 경 (mm) | C33: 입경별 구성비 (%) | D33: 침강속도 (cm/s) | E33: 소요수면적 (m2) | F33: 포착율 (%) | G33: 입경별 포착율 (%)
A34: 2 | C34: 14.9 | D34: 10 | E34: =ROUND(1.2*$B$10/D34*100,0) -> 6 | F34: =ROUND(IF(100*$F$21/E34>=100,100,100*$F$21/E34),1) -> 0 | G34: =ROUND(C34*F34/100,1) -> 0
A35: 0.1 | C35: 48.9 | D35: 0.74 | E35: =ROUND(1.2*$B$10/D35*100,0) -> 82 | F35: =ROUND(IF(100*$F$21/E35>=100,100,100*$F$21/E35),1) -> 0 | G35: =ROUND(C35*F35/100,1) -> 0
A36: 0.05 | C36: 5 | D36: 0.17 | E36: =ROUND(1.2*$B$10/D36*100,0) -> 357 | F36: =ROUND(IF(100*$F$21/E36>=100,100,100*$F$21/E36),1) -> 0 | G36: =ROUND(C36*F36/100,1) -> 0
A37: 0.002 | C37: 27.5 | D37: 0.00028 | E37: =ROUND(1.2*$B$10/D37*100,0) -> 216557 | F37: =ROUND(IF(100*$F$21/E37>=100,100,100*$F$21/E37),1) -> 0 | G37: =ROUND(C37*F37/100,1) -> 0
A38: 0.001 | C38: 18.6 | D38: 6.9e-05 | E38: =ROUND(1.2*$B$10/D38*100,0) -> 878783 | F38: =ROUND(IF(100*$F$21/E38>=100,100,100*$F$21/E38),1) -> 0 | G38: =ROUND(C38*F38/100,1) -> 0
G39: =SUM(G34:G38) -> 0
